Workbook

Sheet Summary
A1: Metric | B1: Value
A2: Total Pokémon | B2: 1025
A3: Number of Game Titles (columns per section) | B3: 45
A4: Game Titles (chronological) | B4: Red, Blue, Yellow, Gold, Silver, Crystal, Ruby, Sapphire, Emerald, FireRed, LeafGreen, Diamond, Pearl, Platinum, HeartGold, SoulSilver, Black, White, Black 2, White 2, X, Y, Omega Ruby, Alpha Sapphire, Sun, Moon, Ultra Sun, Ultra Moon, Let's Go Pikachu, Let's Go Eevee, Sword, Shield, The Isle of Armor, The Crown Tundra, Brilliant Diamond, Shining Pearl, Legends: Arceus, Scarlet, Violet, The Teal Mask, The Indigo Disk, Legends: Z-A, Legends: Z, U.Moon, U.Sun
A5: Columns (base) | B5: 27
A6: Columns (Local #) | B6: 45
A7: Columns (Dex Text) | B7: 45
A8: Columns (Where to Find) | B8: 45
A9: Total Columns | B9: 162

Sheet MasterDex
Y1: Base Stats | AG1: =image("https://img.pokemondb.net/boxes/avif/"&lower(AG2)&".avif") | AH1: =image("https://img.pokemondb.net/boxes/avif/"&lower(AH2)&".avif") | AI1: =image("https://img.pokemondb.net/boxes/avif/"&lower(AI2)&".avif") | AJ1: =image("https://img.pokemondb.net/boxes/avif/"&lower(AJ2)&".avif") | AK1: =image("https://img.pokemondb.net/boxes/avif/"&lower(AK2)&".avif") | AL1: =image("https://img.pokemondb.net/boxes/avif/"&lower(AL2)&".avif") | AM1: =image("https://img.pokemondb.net/boxes/avif/"&lower(AM2)&".avif") | AN1: =image("https://img.pokemondb.net/boxes/avif/"&lower(AN2)&".avif") | ... BH1: =image("https://img.pokemondb.net/boxes/avif/"&lower(BH2)&".avif") | BI1: =image("https://img.pokemondb.net/boxes/lg/"&lower(BI2)&"-large.jpg") | BJ1: =image("https://img.pokemondb.net/boxes/lg/"&lower(BJ2)&"-large.jpg") | BK1: =image("https://img.pokemondb.net/boxes/lg/"&lower(BK2)&"-large.jpg") | BL1: =image("https://img.pokemondb.net/boxes/lg/"&lower(BL2)&"-large.jpg") | BM1: =image("https://assets-prd.ignimgs.com/2020/06/23/pokemon-sword-shield-dlc-the-isle-of-armor-button-00-1592945233643.jpg?crop=1%3A1%2Csmart&format=jpg&auto=webp&quality=80") | BN1: =image("https://assets-prd.ignimgs.com/2020/06/23/pokemon-sword-shield-dlc-the-crown-tundra-button-00-1592945232346.jpg?crop=1%3A1%2Csmart&format=jpg&auto=webp&quality=80") | BO1: =image("https://img.pokemondb.net/boxes/lg/"&lower(BO2)&"-large.jpg") | BP1: =image("https://img.pokemondb.net/boxes/lg/"&lower(BP2)&"-large.jpg") | BQ1: =image("https://img.pokemondb.net/boxes/lg/"&lower(BQ2)&"-large.jpg") | BR1: =image("https://img.pokemondb.net/boxes/lg/"&lower(BR2)&"-large.jpg") | BS1: =image("https://img.pokemondb.net/boxes/lg/"&lower(BS2)&"-large.jpg") | BT1: =image("https://archives.bulbagarden.net/media/upload/thumb/e/ea/SV_eShop_Part_1_The_Teal_Mask.jpg/250px-SV_eShop_Part_1_The_Teal_Mask.jpg") | BU1: =image("https://pokemongohub.net/wp-content/uploads/2023/12/the-indigo-disk.jpg") | BV1: =image("https://archives.bulbagarden.net/media/upload/thumb/b/bd/Legends_Z-A_Nintendo_Switch_2_Edition_EN_boxart.png/250px-Legends_Z-A_Nintendo_Switch_2_Edition_EN_boxart.png")
A2: ref_id | B2: National Dex Number | C2: Name | D2: Sprite | E2: Shiny | F2: Type 1 | G2: Type 2 | H2: Type 1 Helper | I2: Type 2 Helper | J2: Species | K2: Height | L2: Weight | M2: Ability 1 | N2: Ability 2 | O2: Hidden Ability | P2: EV Yield | Q2: Catch Rate | R2: Base Friendship | S2: Base EXP | T2: Growth Rate | U2: Egg Group 1 | V2: Egg Group 2 | W2: Gender Ratio | X2: Egg Cycles | Y2: HP | Z2: Attack | AA2: Defense | AB2: Sp. Atk | AC2: Sp. Def | AD2: Speed | AE2: Total | AF2: Evolution Chain | AG2: Red | AH2: Blue | AI2: Yellow | AJ2: Gold | AK2: Silver | AL2: Crystal | AM2: Ruby | AN2: Sapphire | AO2: Emerald | AP2: FireRed | AQ2: LeafGreen | AR2: Diamond | AS2: Pearl | AT2: Platinum | AU2: HeartGold | AV2: SoulSilver | AW2: Black | AX2: White | AY2: Black-2 | AZ2: White-2 | BA2: X | BB2: Y | BC2: Omega-Ruby | BD2: Alpha-Sapphire | BE2: Sun | BF2: Moon | BG2: Ultra-Sun | BH2: Ultra-Moon | BI2: Lets-Go-Pikachu | BJ2: Lets-Go-Eevee | BK2: Sword | BL2: Shield | BM2: The-Isle-Of-Armor | BN2: The Crown Tundra | BO2: Brilliant-Diamond | BP2: Shining-Pearl | BQ2: Legends-Arceus | BR2: Scarlet | BS2: Violet | BT2: The-Teal-Mask | BU2: The-Indigo-Disk | BV2: Legends-Z-A | BW2: Red Dex Text | BX2: Blue Dex Text | BY2: Yellow Dex Text | BZ2: Gold Dex Text | CA2: Silver Dex Text | CB2: Crystal Dex Text | CC2: Ruby Dex Text | CD2: Sapphire Dex Text | CE2: Emerald Dex Text | CF2: FireRed Dex Text | CG2: LeafGreen Dex Text | CH2: Diamond Dex Text | CI2: Pearl Dex Text | CJ2: Platinum Dex Text | CK2: HeartGold Dex Text | CL2: SoulSilver Dex Text | CM2: Black Dex Text | CN2: White Dex Text | CO2: Black 2 Dex Text | CP2: White 2 Dex Text | CQ2: X Dex Text | CR2: Y Dex Text | CS2: Omega Ruby Dex Text | CT2: Alpha Sapphire Dex Text | CU2: Sun Dex Text | CV2: Moon Dex Text | CW2: Ultra Sun Dex Text | CX2: Ultra Moon Dex Text | CY2: Let's Go Pikachu Dex Text | CZ2: Let's Go Eevee Dex Text | DA2: Sword Dex Text | DB2: Shield Dex Text | DC2: The Isle of Armor Dex Text | DD2: The Crown Tundra Dex Text | DE2: Brilliant Diamond Dex Text | DF2: Shining Pearl Dex Text | DG2: Legends: Arceus Dex Text | DH2: Scarlet Dex Text | DI2: Violet Dex Text | DJ2: The Teal Mask Dex Text | DK2: The Indigo Disk Dex Text | DL2: Legends: Z-A Dex Text | DM2: Legends: Z Dex Text | DN2: U.Moon Dex Text | DO2: U.Sun Dex Text | DP2: Red Location | DQ2: Blue Location | DR2: Yellow Location | DS2: Gold Location | DT2: Silver Location | DU2: Crystal Location | DV2: Ruby Location | DW2: Sapphire Location | DX2: Emerald Location | DY2: FireRed Location | DZ2: LeafGreen Location | EA2: Diamond Location | EB2: Pearl Location | EC2: Platinum Location | ED2: HeartGold Location | EE2: SoulSilver Location | EF2: Black Location | EG2: White Location | EH2: Black 2 Location | EI2: White 2 Location | EJ2: X Location | EK2: Y Location | EL2: Omega Ruby Location | EM2: Alpha Sapphire Location | EN2: Sun Location | EO2: Moon Location | EP2: Ultra Sun Location | EQ2: Ultra Moon Location | ER2: Let's Go Pikachu Location | ES2: Let's Go Eevee Location | ET2: Sword Location | EU2: Shield Location | EV2: The Isle of Armor Location | EW2: The Crown Tundra Location | EX2: Brilliant Diamond Location | EY2: Shining Pearl Location | EZ2: Legends: Arceus Location | FA2: Scarlet Location | FB2: Violet Location | FC2: The Teal Mask Location | FD2: The Indigo Disk Location | FE2: Legends: Z-A Location
A3: 0001-00 | B3: 1 | C3: Bulbasaur | D3: =image("https://img.pokemondb.net/sprites/home/normal/"& lower(C3) &".png") | E3: =image("https://img.pokemondb.net/sprites/home/shiny/"& lower(C3) &".png") | F3: =image("https://www.serebii.net/pokedex-bw/type/"&lower(H3)&".gif") | G3: =image("https://www.serebii.net/pokedex-bw/type/"&lower(I3)&".gif") | H3: Grass | I3: Poison | J3: Seed Pokémon | K3: 0.7 m (2′04″) | L3: 6.9 kg (15.2 lbs) | M3: Overgrow | O3: Chlorophyll | P3: 1 Sp. Atk | Q3: 45 (5.9% with PokéBall, full HP) | R3: 50 (normal) | S3: 64 | T3: Medium Slow | U3: Grass | V3: Monster | W3: 87.5% male, 12.5% female | X3: 20 (4,884–5,140 steps) | Y3: 45 | Z3: 49 | AA3: 49 | AB3: 65 | AC3: 65 | AD3: 45 | AE3: =sum(Y3:AD3) -> 318 | AF3: Bulbasaur → Ivysaur (Level 16) → Venusaur (Level 32) | AG3: 0001 | AH3: 0001 | AI3: 0001 | AJ3: 0226 | AK3: 0226 | AL3: 0226 | AP3: 0001 | AQ3: 0001 | AU3: 0231 | AV3: 0231 | BA3: 0080 | BB3: 0080 | BI3: 0001 | BJ3: 0001 | BM3: 0068 | BU3: 0164 | BV3: 0148 | BW3: A strange seed was planted on its back at birth. The plant sprouts and grows with this POKéMON. | BX3: A strange seed was planted on its back at birth. The plant sprouts and grows with this POKéMON. | BY3: It can go for days without eating a single morsel. In the bulb on its back, it stores energy. | BZ3: The seed on its back is filled with nutrients. The seed grows steadily larger as its body grows. | CA3: It carries a seed on its back right from birth. As it grows older, the seed also grows larger. | CB3: While it is young, it uses the nutrients that are stored in the seeds on its back in order to grow. | CC3: BULBASAUR can be seen napping in bright sunlight. There is a seed on its back. By soaking up the sun’s rays, the seed grows progressively larger. | CD3: BULBASAUR can be seen napping in bright sunlight. There is a seed on its back. By soaking up the sun’s rays, the seed grows progressively larger. | CE3: BULBASAUR can be seen napping in bright sunlight. There is a seed on its back. By soaking up the sun’s rays, the seed grows progressively larger. | CF3: There is a plant seed on its back right from the day this POKéMON is born. The seed slowly grows larger. | CG3: A strange seed was planted on its back at birth. The plant sprouts and grows with this POKéMON. | CH3: For some time after its birth, it grows by gaining nourishment from the seed on its back. | CI3: For some time after its birth, it grows by gaining nourishment from the seed on its back. | CJ3: For some time after its birth, it grows by gaining nourishment from the seed on its back. | CK3: The seed on its back is filled with nutrients. The seed grows steadily larger as its body grows. | CL3: It carries a seed on its back right from birth. As it grows older, the seed also grows larger. | CM3: For some time after its birth, it grows by gaining nourishment from the seed on its back. | CN3: For some time after its birth, it grows by gaining nourishment from the seed on its back. | CO3: For some time after its birth, it grows by gaining nourishment from the seed on its back. | CP3: For some time after its birth, it grows by gaining nourishment from the seed on its back. | CQ3: A strange seed was planted on its back at birth. The plant sprouts and grows with this Pokémon. | CR3: For some time after its birth, it grows by gaining nourishment from the seed on its back. | CS3: Bulbasaur can be seen napping in bright sunlight. There is a seed on its back. By soaking up the sun’s rays, the seed grows progressively larger. | CT3: Bulbasaur can be seen napping in bright sunlight. There is a seed on its back. By soaking up the sun’s rays, the seed grows progressively larger. | CY3: It can go for days without eating a single morsel. In the bulb on its back, it stores energy. | CZ3: It can go for days without eating a single morsel. In the bulb on its back, it stores energy. | DA3: There is a plant seed on its back right from the day this Pokémon is born. The seed slowly grows larger. | DB3: While it is young, it uses the nutrients that are stored in the seed on its back in order to grow. | DE3: For some time after its birth, it grows by taking nourishment from the seed on its back. | DF3: For some time after its birth, it grows by taking nourishment from the seed on its back. | DP3: Pallet Town | DQ3: Pallet Town | DR3: Cerulean City | DS3: Trade/migrate from another game | DT3: Trade/migrate from another game | DU3: Trade/migrate from another game | DV3: Trade/migrate from another game | DW3: Trade/migrate from another game | DX3: Trade/migrate from another game | DY3: Pallet Town | DZ3: Pallet Town | EA3: Trade/migrate from another game | EB3: Trade/migrate from another game | EC3: Trade/migrate from another game | ED3: Pallet Town | EE3: Pallet Town | EF3: Trade/migrate from another game | EG3: Trade/migrate from another game | EH3: Trade/migrate from another game | EI3: Trade/migrate from another game | EJ3: Lumiose City | EK3: Lumiose City | EL3: Trade/migrate from another game | EM3: Trade/migrate from another game | EN3: Trade/migrate from another game | EO3: Trade/migrate from another game | EP3: Route 2 | EQ3: Route 2 | ER3: Cerulean City , Viridian Forest | ES3: Cerulean City , Viridian Forest | ET3: Trade/migrate from another game | EU3: Trade/migrate from another game | EX3: Grassland Cave , Swampy Cave , Riverbank Cave , Still-Water Cavern , Sunlit Cavern , Bogsunk Cavern | EY3: Grassland Cave , Swampy Cave , Riverbank Cave , Still-Water Cavern , Sunlit Cavern , Bogsunk Cavern | EZ3: Not available in this game | FA3: Location data not yet available | FB3: Location data not yet available | FE3: Location data not yet available
A4: 0002-00 | B4: 2 | C4: Ivysaur | D4: =image("https://img.pokemondb.net/sprites/home/normal/"& lower(C4) &".png") | E4: =image("https://img.pokemondb.net/sprites/home/shiny/"& lower(C4) &".png") | F4: =image("https://www.serebii.net/pokedex-bw/type/"&lower(H4)&".gif") | G4: =image("https://www.serebii.net/pokedex-bw/type/"&lower(I4)&".gif") | H4: Grass | I4: Poison | J4: Seed Pokémon | K4: 1.0 m (3′03″) | L4: 13.0 kg (28.7 lbs) | M4: Overgrow | O4: Chlorophyll | P4: 1 Sp. Atk, 1 Sp. Def | Q4: 45 (5.9% with PokéBall, full HP) | R4: 50 (normal) | S4: 142 | T4: Medium Slow | U4: Grass | V4: Monster | W4: 87.5% male, 12.5% female | X4: 20 (4,884–5,140 steps) | Y4: 60 | Z4: 62 | AA4: 63 | AB4: 80 | AC4: 80 | AD4: 60 | AE4: =sum(Y4:AD4) -> 405 | AF4: Bulbasaur → Ivysaur (Level 16) → Venusaur (Level 32) | AG4: 0002 | AH4: 0002 | AI4: 0002 | AJ4: 0227 | AK4: 0227 | AL4: 0227 | AP4: 0002 | AQ4: 0002 | AU4: 0232 | AV4: 0232 | BA4: 0081 | BB4: 0081 | BI4: 0002 | BJ4: 0002 | BM4: 0069 | BU4: 0165 | BV4: 0149 | BW4: When the bulb on its back grows large, it appears to lose the ability to stand on its hind legs. | BX4: When the bulb on its back grows large, it appears to lose the ability to stand on its hind legs. | BY4: The bulb on its back grows by drawing energy. It gives off an aroma when it is ready to bloom. | BZ4: Exposure to sunlight adds to its strength. Sunlight also makes the bud on its back grow larger. | CA4: If the bud on its back starts to smell sweet, it is evidence that the large flower will soon bloom. | CB4: The bulb on its back grows as it absorbs nutrients. The bulb gives off a pleasant aroma when it blooms. | CC4: There is a bud on this POKéMON’s back. To support its weight, IVYSAUR’s legs and trunk grow thick and strong. If it starts spending more time lying in the sunlight, it’s a sign that the bud will bloom into a large flower soon. | CD4: There is a bud on this POKéMON’s back. To support its weight, IVYSAUR’s legs and trunk grow thick and strong. If it starts spending more time lying in the sunlight, it’s a sign that the bud will bloom into a large flower soon. | CE4: To support its bulb, IVYSAUR’s legs grow sturdy. If it spends more time lying in the sunlight, the bud will soon bloom into a large flower. | CF4: There is a plant bulb on its back. When it absorbs nutrients, the bulb is said to blossom into a large flower. | CG4: When the bulb on its back grows large, it appears to lose the ability to stand on its hind legs. | CH4: When the bud on its back starts swelling, a sweet aroma wafts to indicate the flower’s coming bloom. | CI4: When the bud on its back starts swelling, a sweet aroma wafts to indicate the flower’s coming bloom. | CJ4: When the bud on its back starts swelling, a sweet aroma wafts to indicate the flower’s coming bloom. | CK4: Exposure to sunlight adds to its strength. Sunlight also makes the bud on its back grow larger. | CL4: If the bud on its back starts to smell sweet, it is evidence that the large flower will soon bloom. | CM4: When the bud on its back starts swelling, a sweet aroma wafts to indicate the flower’s coming bloom. | CN4: When the bud on its back starts swelling, a sweet aroma wafts to indicate the flower’s coming bloom. | CO4: When the bud on its back starts swelling, a sweet aroma wafts to indicate the flower’s coming bloom. | CP4: When the bud on its back starts swelling, a sweet aroma wafts to indicate the flower’s coming bloom. | CQ4: There is a plant bulb on its back. When it absorbs nutrients, the bulb is said to blossom into a large flower. | CR4: When the bud on its back starts swelling, a sweet aroma wafts to indicate the flower’s coming bloom. | CS4: There is a bud on this Pokémon’s back. To support its weight, Ivysaur’s legs and trunk grow thick and strong. If it starts spending more time lying in the sunlight, it’s a sign that the bud will bloom into a large flower soon. | CT4: There is a bud on this Pokémon’s back. To support its weight, Ivysaur’s legs and trunk grow thick and strong. If it starts spending more time lying in the sunlight, it’s a sign that the bud will bloom into a large flower soon. | CY4: The bud on its back grows by drawing energy. It gives off an aroma when it is ready to bloom. | CZ4: The bud on its back grows by drawing energy. It gives off an aroma when it is ready to bloom. | DA4: When the bulb on its back grows large, it appears to lose the ability to stand on its hind legs. | DB4: Exposure to sunlight adds to its strength. Sunlight also makes the bud on its back grow larger. | DE4: When the bud on its back starts swelling, a sweet aroma wafts to indicate the flower’s coming bloom. | DF4: When the bud on its back starts swelling, a sweet aroma wafts to indicate the flower’s coming bloom. | DP4: Evolve Bulbasaur | DQ4: Evolve Bulbasaur | DR4: Evolve Bulbasaur | DS4: Trade/migrate from another game | DT4: Trade/migrate from another game | DU4: Trade/migrate from another game | DV4: Trade/migrate from another game | DW4: Trade/migrate from another game | DX4: Trade/migrate from another game | DY4: Evolve Bulbasaur | DZ4: Evolve Bulbasaur | EA4: Trade/migrate from another game | EB4: Trade/migrate from another game | EC4: Trade/migrate from another game | ED4: Evolve Bulbasaur | EE4: Evolve Bulbasaur | EF4: Trade/migrate from another game | EG4: Trade/migrate from another game | EH4: Trade/migrate from another game | EI4: Trade/migrate from another game | EJ4: Evolve Bulbasaur | EK4: Evolve Bulbasaur | EL4: Trade/migrate from another game | EM4: Trade/migrate from another game | EN4: Trade/migrate from another game | EO4: Trade/migrate from another game | EP4: Evolve Bulbasaur | EQ4: Evolve Bulbasaur | ER4: Evolve Bulbasaur | ES4: Evolve Bulbasaur | ET4: Trade/migrate from another game | EU4: Trade/migrate from another game | EX4: Evolve Bulbasaur | EY4: Evolve Bulbasaur | EZ4: Not available in this game | FA4: Location data not yet available | FB4: Location data not yet available | FE4: Location data not yet available
A5: 0003-00 | B5: 3 | C5: Venusaur | D5: =image("https://img.pokemondb.net/sprites/home/normal/"& lower(C5) &".png") | E5: =image("https://img.pokemondb.net/sprites/home/shiny/"& lower(C5) &".png") | F5: =image("https://www.serebii.net/pokedex-bw/type/"&lower(H5)&".gif") | G5: =image("https://www.serebii.net/pokedex-bw/type/"&lower(I5)&".gif") | H5: Grass | I5: Poison | J5: Seed Pokémon | K5: 2.0 m (6′07″) | L5: 100.0 kg (220.5 lbs) | M5: Overgrow | O5: Chlorophyll | P5: 2 Sp. Atk, 1 Sp. Def | Q5: 45 (5.9% with PokéBall, full HP) | R5: 50 (normal) | S5: 236 | T5: Medium Slow | U5: Grass | V5: Monster | W5: 87.5% male, 12.5% female | X5: 20 (4,884–5,140 steps) | Y5: 80 | Z5: 82 | AA5: 83 | AB5: 100 | AC5: 100 | AD5: 80 | AE5: =sum(Y5:AD5) -> 525 | AF5: Bulbasaur → Ivysaur (Level 16) → Venusaur (Level 32) | AG5: 0003 | AH5: 0003 | AI5: 0003 | AJ5: 0228 | AK5: 0228 | AL5: 0228 | AP5: 0003 | AQ5: 0003 | AU5: 0233 | AV5: 0233 | BA5: 0082 | BB5: 0082 | BI5: 0003 | BJ5: 0003 | BM5: 0070 | BU5: 0166 | BV5: 0150 | BW5: The plant blooms when it is absorbing solar energy. It stays on the move to seek sunlight. | BX5: The plant blooms when it is absorbing solar energy. It stays on the move to seek sunlight. | BY5: The flower on its back catches the sun’s rays. The sunlight is then absorbed and used for energy. | BZ5: By spreading the broad petals of its flower and catching the sun’s rays, it fills its body with power. | CA5: It is able to convert sunlight into energy. As a result, it is more powerful in the summertime. | CB5: As it warms itself and absorbs the sunlight, its flower petals release a pleasant fragrance. | CC5: There is a large flower on VENUSAUR’s back. The flower is said to take on vivid colors if it gets plenty of nutrition and sunlight. The flower’s aroma soothes the emotions of people. | CD5: There is a large flower on VENUSAUR’s back. The flower is said to take on vivid colors if it gets plenty of nutrition and sunlight. The flower’s aroma soothes the emotions of people. | CE5: VENUSAUR’s flower is said to take on vivid colors if it gets plenty of nutrition and sunlight. The flower’s aroma soothes the emotions of people. | CF5: A bewitching aroma wafts from its flower. The fragrance becalms those engaged in a battle. | CG5: Its plant blooms when it is absorbing solar energy. It stays on the move to seek sunlight. | CH5: After a rainy day, the flower on its back smells stronger. The scent attracts other Pokémon. | CI5: After a rainy day, the flower on its back smells stronger. The scent attracts other Pokémon. | CJ5: After a rainy day, the flower on its back smells stronger. The scent attracts other Pokémon. | CK5: By spreading the broad petals of its flower and catching the sun’s rays, it fills its body with power. | CL5: It is able to convert sunlight into energy. As a result, it is more powerful in the summertime. | CM5: After a rainy day, the flower on its back smells stronger. The scent attracts other Pokémon. | CN5: After a rainy day, the flower on its back smells stronger. The scent attracts other Pokémon. | CO5: After a rainy day, the flower on its back smells stronger. The scent attracts other Pokémon. | CP5: After a rainy day, the flower on its back smells stronger. The scent attracts other Pokémon. | CQ5: By spreading the broad petals of its flower and catching the sun’s rays, it fills its body with power. | CR5: After a rainy day, the flower on its back smells stronger. The scent attracts other Pokémon. | CS5: There is a large flower on Venusaur’s back. The flower is said to take on vivid colors if it gets plenty of nutrition and sunlight. The flower’s aroma soothes the emotions of people. | CT5: There is a large flower on Venusaur’s back. The flower is said to take on vivid colors if it gets plenty of nutrition and sunlight. The flower’s aroma soothes the emotions of people. | CY5: The flower on its back catches the sun’s rays. The sunlight is then absorbed and used for energy. | CZ5: The flower on its back catches the sun’s rays. The sunlight is then absorbed and used for energy. | DA5: Its plant blooms when it is absorbing solar energy. It stays on the move to seek sunlight. | DB5: A bewitching aroma wafts from its flower. The fragrance becalms those engaged in a battle. | DE5: After a rainy day, the flower on its back smells stronger. The scent attracts other Pokémon. | DF5: After a rainy day, the flower on its back smells stronger. The scent attracts other Pokémon. | DP5: Evolve Bulbasaur / Ivysaur | DQ5: Evolve Bulbasaur / Ivysaur | DR5: Evolve Bulbasaur / Ivysaur | DS5: Trade/migrate from another game | DT5: Trade/migrate from another game | DU5: Trade/migrate from another game | DV5: Trade/migrate from another game | DW5: Trade/migrate from another game | DX5: Trade/migrate from another game | DY5: Evolve Bulbasaur / Ivysaur | DZ5: Evolve Bulbasaur / Ivysaur | EA5: Trade/migrate from another game | EB5: Trade/migrate from another game | EC5: Trade/migrate from another game | ED5: Evolve Bulbasaur / Ivysaur | EE5: Evolve Bulbasaur / Ivysaur | EF5: Trade/migrate from another game | EG5: Trade/migrate from another game | EH5: Trade/migrate from another game | EI5: Trade/migrate from another game | EJ5: Evolve Bulbasaur / Ivysaur | EK5: Evolve Bulbasaur / Ivysaur | EL5: Trade/migrate from another game | EM5: Trade/migrate from another game | EN5: Trade/migrate from another game | EO5: Trade/migrate from another game | EP5: Evolve Bulbasaur / Ivysaur | EQ5: Evolve Bulbasaur / Ivysaur | ER5: Evolve Bulbasaur / Ivysaur | ES5: Evolve Bulbasaur / Ivysaur | ET5: Trade/migrate from another game | EU5: Trade/migrate from another game | EX5: Evolve Bulbasaur / Ivysaur | EY5: Evolve Bulbasaur / Ivysaur | EZ5: Not available in this game | FA5: Location data not yet available | FB5: Location data not yet available | FE5: Location data not yet available
A6: 0003-01 | B6: 3 | C6: Mega Venusaur | D6: =Sprite_Data!F2 | E6: =Sprite_Data!G2 | F6: =image("https://www.serebii.net/pokedex-bw/type/"&lower(H6)&".gif") | G6: =image("https://www.serebii.net/pokedex-bw/type/"&lower(I6)&".gif") | H6: Grass | I6: Poison | J6: Seed Pokémon | K6: 2.0 m (6′07″) | L6: 100.0 kg (220.5 lbs) | M6: Thick Fat | P6: 3 Sp. Atk, 1 Sp. Def | Q6: 46 (5.9% with PokéBall, full HP) | R6: 51 (normal) | S6: 281 | T6: Medium Slow | U6: Grass | V6: Monster | W6: 87.5% male, 12.5% female | X6: 21 (4,884–5,140 steps) | Y6: 80 | Z6: 100 | AA6: 123 | AB6: 122 | AC6: 120 | AD6: 80 | AE6: =sum(Y6:AD6) -> 625 | AF6: Venusaurite | AG6: 0004 | AH6: 0004 | AI6: 0004 | AJ6: 0229 | AK6: 0229 | AL6: 0229 | AP6: 0004 | AQ6: 0004 | AU6: 0234 | AV6: 0234 | BA6: 0083 | BB6: 0083 | BI6: 0004 | BJ6: 0004 | BM6: 0071 | BU6: 0167 | BV6: 0151
A7: 0003-02 | B7: 3 | C7: Venusaur Gigantamax | D7: =Sprite_Data!J2 | E7: =Sprite_Data!K2 | F7: =image("https://www.serebii.net/pokedex-bw/type/"&lower(H7)&".gif") | G7: =image("https://www.serebii.net/pokedex-bw/type/"&lower(I7)&".gif") | H7: Grass | I7: Poison | J7: Seed Pokémon | K7: 24.0 m (78'09") | M7: Overgrow | O7: Chlorophyll | AE7: =sum(Y7:AD7) -> 0 | AF7: Dynamax Band
A8: 0004-00 | B8: 4 | C8: Charmander | D8: =image("https://img.pokemondb.net/sprites/home/normal/"& lower(C8) &".png") | E8: =image("https://img.pokemondb.net/sprites/home/shiny/"& lower(C8) &".png") | F8: =image("https://www.serebii.net/pokedex-bw/type/"&lower(H8)&".gif") | G8: =image("https://www.serebii.net/pokedex-bw/type/"&lower(I8)&".gif") | H8: Fire | J8: Lizard Pokémon | K8: 0.6 m (2′00″) | L8: 8.5 kg (18.7 lbs) | M8: Blaze | O8: Solar Power | P8: 1 Speed | Q8: 45 (5.9% with PokéBall, full HP) | R8: 50 (normal) | S8: 62 | T8: Medium Slow | U8: Dragon | V8: Monster | W8: 87.5% male, 12.5% female | X8: 20 (4,884–5,140 steps) | Y8: 39 | Z8: 52 | AA8: 43 | AB8: 60 | AC8: 50 | AD8: 65 | AE8: =sum(Y8:AD8) -> 309 | AF8: Charmander → Charmeleon (Level 16) → Charizard (Level 36) | AG8: 0004 | AH8: 0004 | AI8: 0004 | AJ8: 0229 | AK8: 0229 | AL8: 0229 | AP8: 0004 | AQ8: 0004 | AU8: 0234 | AV8: 0234 | BA8: 0083 | BB8: 0083 | BI8: 0004 | BJ8: 0004 | BK8: 0378 | BL8: 0378 | BU8: 0167 | BV8: 0151 | BW8: Obviously prefers hot places. When it rains, steam is said to spout from the tip of its tail. | BX8: Obviously prefers hot places. When it rains, steam is said to spout from the tip of its tail. | BY8: The flame at the tip of its tail makes a sound as it burns. You can only hear it in quiet places. | BZ8: The flame on its tail shows the strength of its life force. If it is weak, the flame also burns weakly. | CA8: The flame on its tail indicates CHARMANDER’s life force. If it is healthy, the flame burns brightly. | CB8: If it’s healthy, the flame on the tip of its tail will burn vigorously, even if it gets a bit wet. | CC8: The flame that burns at the tip of its tail is an indication of its emotions. The flame wavers when CHARMANDER is enjoying itself. If the POKéMON becomes enraged, the flame burns fiercely. | CD8: The flame that burns at the tip of its tail is an indication of its emotions. The flame wavers when CHARMANDER is enjoying itself. If the POKéMON becomes enraged, the flame burns fiercely. | CE8: The flame that burns at the tip of its tail is an indication of its emotions. The flame wavers when CHARMANDER is happy, and blazes when it is enraged. | CF8: From the time it is born, a flame burns at the tip of its tail. Its life would end if the flame were to go out. | CG8: It has a preference for hot things. When it rains, steam is said to spout from the tip of its tail. | CH8: The fire on the tip of its tail is a measure of its life. If healthy, its tail burns intensely. | CI8: The fire on the tip of its tail is a measure of its life. If healthy, its tail burns intensely. | CJ8: The fire on the tip of its tail is a measure of its life. If healthy, its tail burns intensely. | CK8: The flame on its tail shows the strength of its life force. If it is weak, the flame also burns weakly. | CL8: The flame on its tail indicates CHARMANDER’s life force. If it is healthy, the flame burns brightly. | CM8: The fire on the tip of its tail is a measure of its life. If healthy, its tail burns intensely. | CN8: The fire on the tip of its tail is a measure of its life. If healthy, its tail burns intensely. | CO8: The fire on the tip of its tail is a measure of its life. If healthy, its tail burns intensely. | CP8: The fire on the tip of its tail is a measure of its life. If healthy, its tail burns intensely. | CQ8: The flame on its tail indicates Charmander’s life force. If it is healthy, the flame burns brightly. | CR8: From the time it is born, a flame burns at the tip of its tail. Its life would end if the flame were to go out. | CS8: The flame that burns at the tip of its tail is an indication of its emotions. The flame wavers when Charmander is enjoying itself. If the Pokémon becomes enraged, the flame burns fiercely. | CT8: The flame that burns at the tip of its tail is an indication of its emotions. The flame wavers when Charmander is enjoying itself. If the Pokémon becomes enraged, the flame burns fiercely. | CY8: The flame at the tip of its tail makes a sound as it burns. You can only hear it in quiet places. | CZ8: The flame at the tip of its tail makes a sound as it burns. You can only hear it in quiet places. | DA8: It has a preference for hot things. When it rains, steam is said to spout from the tip of its tail. | DB8: From the time it is born, a flame burns at the tip of its tail. Its life would end if the flame were to go out. | DE8: The fire on the tip of its tail is a measure of its life. If the Pokémon is healthy, its tail burns intensely. | DF8: The fire on the tip of its tail is a measure of its life. If the Pokémon is healthy, its tail burns intensely. | DP8: Pallet Town | DQ8: Pallet Town | DR8: Route 24 | DS8: Trade/migrate from another game | DT8: Trade/migrate from another game | DU8: Trade/migrate from another game | DV8: Trade/migrate from another game | DW8: Trade/migrate from another game | DX8: Trade/migrate from another game | DY8: Pallet Town | DZ8: Pallet Town | EA8: Trade/migrate from another game | EB8: Trade/migrate from another game | EC8: Trade/migrate from another game | ED8: Pallet Town | EE8: Pallet Town | EF8: Trade/migrate from another game | EG8: Trade/migrate from another game | EH8: Trade/migrate from another game | EI8: Trade/migrate from another game | EJ8: Lumiose City | EK8: Lumiose City | EL8: Trade/migrate from another game | EM8: Trade/migrate from another game | EN8: Trade/migrate from another game | EO8: Trade/migrate from another game | EP8: Route 3 | EQ8: Route 3 | ER8: Route 3 , 4 , 24 , Rock Tunnel | ES8: Route 3 , 4 , 24 , Rock Tunnel | ET8: Trade/migrate from another game | EU8: Trade/migrate from another game | EX8: Volcanic Cave , Sandsear Cave , Typhlo Cavern | EY8: Volcanic Cave , Sandsear Cave , Typhlo Cavern | EZ8: Not available in this game | FA8: Location data not yet available | FB8: Location data not yet available | FE8: Location data not yet available
A9: 0005-00 | B9: 5 | C9: Charmeleon | D9: =image("https://img.pokemondb.net/sprites/home/normal/"& lower(C9) &".png") | E9: =image("https://img.pokemondb.net/sprites/home/shiny/"& lower(C9) &".png") | F9: =image("https://www.serebii.net/pokedex-bw/type/"&lower(H9)&".gif") | G9: =image("https://www.serebii.net/pokedex-bw/type/"&lower(I9)&".gif") | H9: Fire | J9: Flame Pokémon | K9: 1.1 m (3′07″) | L9: 19.0 kg (41.9 lbs) | M9: Blaze | O9: Solar Power | P9: 1 Sp. Atk, 1 Speed | Q9: 45 (5.9% with PokéBall, full HP) | R9: 50 (normal) | S9: 142 | T9: Medium Slow | U9: Dragon | V9: Monster | W9: 87.5% male, 12.5% female | X9: 20 (4,884–5,140 steps) | Y9: 58 | Z9: 64 | AA9: 58 | AB9: 80 | AC9: 65 | AD9: 80 | AE9: =sum(Y9:AD9) -> 405 | AF9: Charmander → Charmeleon (Level 16) → Charizard (Level 36) | AG9: 0005 | AH9: 0005 | AI9: 0005 | AJ9: 0230 | AK9: 0230 | AL9: 0230 | AP9: 0005 | AQ9: 0005 | AU9: 0235 | AV9: 0235 | BA9: 0084 | BB9: 0084 | BI9: 0005 | BJ9: 0005 | BK9: 0379 | BL9: 0379 | BU9: 0168 | BV9: 0152 | BW9: When it swings its burning tail, it elevates the temperature to unbearably high levels. | BX9: When it swings its burning tail, it elevates the temperature to unbearably high levels. | BY9: Tough fights could excite this POKéMON. When excited, it may blow out bluish-white flames. | BZ9: It is very hotheaded by nature, so it constantly seeks opponents. It calms down only when it wins. | CA9: It has a barbaric nature. In battle, it whips its fiery tail around and slashes away with sharp claws. | CB9: If it becomes agitated during battle, it spouts intense flames, incinerating its surroundings. | CC9: CHARMELEON mercilessly destroys its foes using its sharp claws. If it encounters a strong foe, it turns aggressive. In this excited state, the flame at the tip of its tail flares with a bluish white color. | CD9: CHARMELEON mercilessly destroys its foes using its sharp claws. If it encounters a strong foe, it turns aggressive. In this excited state, the flame at the tip of its tail flares with a bluish white color. | CE9: Without pity, its sharp claws destroy foes. If it encounters a strong enemy, it becomes agitated, and the flame on its tail flares with a bluish white color. | CF9: It lashes about with its tail to knock down its foe. It then tears up the fallen opponent with sharp claws. | CG9: When it swings its burning tail, it elevates the air temperature to unbearably high levels. | CH9: In the rocky mountains where CHARMELEON live, their fiery tails shine at night like stars. | CI9: In the rocky mountains where CHARMELEON live, their fiery tails shine at night like stars. | CJ9: In the rocky mountains where CHARMELEON live, their fiery tails shine at night like stars. | CK9: It is very hotheaded by nature, so it constantly seeks opponents. It calms down only when it wins. | CL9: It has a barbaric nature. In battle, it whips its fiery tail around and slashes away with sharp claws. | CM9: In the rocky mountains where Charmeleon live, their fiery tails shine at night like stars. | CN9: In the rocky mountains where Charmeleon live, their fiery tails shine at night like stars. | CO9: In the rocky mountains where Charmeleon live, their fiery tails shine at night like stars. | CP9: In the rocky mountains where Charmeleon live, their fiery tails shine at night like stars. | CQ9: It lashes about with its tail to knock down its foe. It then tears up the fallen opponent with sharp claws. | CR9: When it swings its burning tail, it elevates the air temperature to unbearably high levels. | CS9: Charmeleon mercilessly destroys its foes using its sharp claws. If it encounters a strong foe, it turns aggressive. In this excited state, the flame at the tip of its tail flares with a bluish white color. | CT9: Charmeleon mercilessly destroys its foes using its sharp claws. If it encounters a strong foe, it turns aggressive. In this excited state, the flame at the tip of its tail flares with a bluish white color. | CY9: Tough fights could excite this Pokémon. When excited, it may breathe out bluish-white flames. | CZ9: Tough fights could excite this Pokémon. When excited, it may breathe out bluish-white flames. | DA9: It has a barbaric nature. In battle, it whips its fiery tail around and slashes away with sharp claws. | DB9: If it becomes agitated during battle, it spouts intense flames, incinerating its surroundings. | DE9: In the rocky mountains where Charmeleon live, their fiery tails shine at night like stars. | DF9: In the rocky mountains where Charmeleon live, their fiery tails shine at night like stars. | DP9: Evolve Charmander | DQ9: Evolve Charmander | DR9: Evolve Charmander | DS9: Trade/migrate from another game | DT9: Trade/migrate from another game | DU9: Trade/migrate from another game | DV9: Trade/migrate from another game | DW9: Trade/migrate from another game | DX9: Trade/migrate from another game | DY9: Evolve Charmander | DZ9: Evolve Charmander | EA9: Trade/migrate from another game | EB9: Trade/migrate from another game | EC9: Trade/migrate from another game | ED9: Evolve Charmander | EE9: Evolve Charmander | EF9: Trade/migrate from another game | EG9: Trade/migrate from another game | EH9: Trade/migrate from another game | EI9: Trade/migrate from another game | EJ9: Evolve Charmander | EK9: Evolve Charmander | EL9: Trade/migrate from another game | EM9: Trade/migrate from another game | EN9: Trade/migrate from another game | EO9: Trade/migrate from another game | EP9: Evolve Charmander | EQ9: Evolve Charmander | ER9: Evolve Charmander | ES9: Evolve Charmander | ET9: Trade/migrate from another game | EU9: Trade/migrate from another game | EX9: Evolve Charmander | EY9: Evolve Charmander | EZ9: Not available in this game | FA9: Location data not yet available | FB9: Location data not yet available | FE9: Location data not yet available
A10: 0006-00 | B10: 6 | C10: Charizard | D10: =image("https://img.pokemondb.net/sprites/home/normal/"& lower(C10) &".png") | E10: =image("https://img.pokemondb.net/sprites/home/shiny/"& lower(C10) &".png") | F10: =image("https://www.serebii.net/pokedex-bw/type/"&lower(H10)&".gif") | G10: =image("https://www.serebii.net/pokedex-bw/type/"&lower(I10)&".gif") | H10: Fire | I10: Flying | J10: Flame Pokémon | K10: 1.7 m (5′07″) | L10: 90.5 kg (199.5 lbs) | M10: Blaze | O10: Solar Power | P10: 3 Sp. Atk | Q10: 45 (5.9% with PokéBall, full HP) | R10: 50 (normal) | S10: 267 | T10: Medium Slow | U10: Dragon | V10: Monster | W10: 87.5% male, 12.5% female | X10: 20 (4,884–5,140 steps) | Y10: 78 | Z10: 84 | AA10: 78 | AB10: 109 | AC10: 85 | AD10: 100 | AE10: =sum(Y10:AD10) -> 534 | AF10: Charmander → Charmeleon (Level 16) → Charizard (Level 36) | AG10: 0006 | AH10: 0006 | AI10: 0006 | AJ10: 0231 | AK10: 0231 | AL10: 0231 | AP10: 0006 | AQ10: 0006 | AU10: 0236 | AV10: 0236 | BA10: 0085 | BB10: 0085 | BI10: 0006 | BJ10: 0006 | BK10: 0380 | BL10: 0380 | BU10: 0169 | BV10: 0153 | BW10: Spits fire that is hot enough to melt boulders. Known to cause forest fires unintentionally. | BX10: Spits fire that is hot enough to melt boulders. Known to cause forest fires unintentionally. | BY10: When expelling a blast of super hot fire, the red flame at the tip of its tail burns more intensely. | BZ10: If CHARIZARD becomes furious, the flame at the tip of its tail flares up in a whitish-blue color. | CA10: Breathing intense, hot flames, it can melt almost anything. Its breath inflicts terrible pain on enemies. | CB10: It uses its wings to fly high. The temperature of its fire increases as it gains experience in battle. | CC10: CHARIZARD flies around the sky in search of powerful opponents. It breathes fire of such great heat that it melts anything. However, it never turns its fiery breath on any opponent weaker than itself. | CD10: CHARIZARD flies around the sky in search of powerful opponents. It breathes fire of such great heat that it melts anything. However, it never turns its fiery breath on any opponent weaker than itself. | CE10: A CHARIZARD flies about in search of strong opponents. It breathes intense flames that can melt any material. However, it will never torch a weaker foe. | CF10: Its wings can carry this POKéMON close to an altitude of 4,600 feet. It blows out fire at very high temperatures. | CG10: It spits fire that is hot enough to melt boulders. It may cause forest fires by blowing flames. | CH10: It is said that CHARIZARD’s fire burns hotter if it has experienced harsh battles. | CI10: It is said that CHARIZARD’s fire burns hotter if it has experienced harsh battles. | CJ10: It is said that CHARIZARD’s fire burns hotter if it has experienced harsh battles. | CK10: If CHARIZARD becomes furious, the flame at the tip of its tail flares up in a light blue shade. | CL10: Breathing intense, hot flames, it can melt almost anything. Its breath inflicts terrible pain on enemies. | CM10: It is said that Charizard’s fire burns hotter if it has experienced harsh battles. | CN10: It is said that Charizard’s fire burns hotter if it has experienced harsh battles. | CO10: It is said that Charizard’s fire burns hotter if it has experienced harsh battles. | CP10: It is said that Charizard’s fire burns hotter if it has experienced harsh battles. | CQ10: When expelling a blast of superhot fire, the red flame at the tip of its tail burns more intensely. | CR10: Its wings can carry this Pokémon close to an altitude of 4,600 feet. It blows out fire at very high temperatures. | CS10: Charizard flies around the sky in search of powerful opponents. It breathes fire of such great heat that it melts anything. However, it never turns its fiery breath on any opponent weaker than itself. | CT10: Charizard flies around the sky in search of powerful opponents. It breathes fire of such great heat that it melts anything. However, it never turns its fiery breath on any opponent weaker than itself. | CY10: When this Pokémon expels a blast of superhot fire, the red flame at the tip of its tails burns more intensely. | CZ10: When this Pokémon expels a blast of superhot fire, the red flame at the tip of its tails burns more intensely. | DA10: It spits fire that is hot enough to melt boulders. It may cause forest fires by blowing flames. | DB10: Its wings can carry this Pokémon close to an altitude of 4,600 feet. It blows out fire at very high temperatures. | DE10: It is said that Charizard’s fire burns hotter if it has experienced harsh battles. | DF10: It is said that Charizard’s fire burns hotter if it has experienced harsh battles. | DP10: Evolve Charmander / Charmeleon | DQ10: Evolve Charmander / Charmeleon | DR10: Evolve Charmander / Charmeleon | DS10: Trade/migrate from another game | DT10: Trade/migrate from another game | DU10: Trade/migrate from another game | DV10: Trade/migrate from another game | DW10: Trade/migrate from another game | DX10: Trade/migrate from another game | DY10: Evolve Charmander / Charmeleon | DZ10: Evolve Charmander / Charmeleon | EA10: Trade/migrate from another game | EB10: Trade/migrate from another game | EC10: Trade/migrate from another game | ED10: Evolve Charmander / Charmeleon | EE10: Evolve Charmander / Charmeleon | EF10: Trade/migrate from another game | EG10: Trade/migrate from another game | EH10: Trade/migrate from another game | EI10: Trade/migrate from another game | EJ10: Evolve Charmander / Charmeleon | EK10: Evolve Charmander / Charmeleon | EL10: Trade/migrate from another game | EM10: Trade/migrate from another game | EN10: Trade/migrate from another game | EO10: Trade/migrate from another game | EP10: Evolve Charmander / Charmeleon | EQ10: Evolve Charmander / Charmeleon | ER10: Route 2 , 3 , 4 , 7 , 8 , 10 , 11 , 12 , 13 , 14 , 15 , 16 , 17 , 18 , 19 , 21 , 22 , 23 , 24 , 25 | ES10: Route 2 , 3 , 4 , 7 , 8 , 10 , 11 , 12 , 13 , 14 , 15 , 16 , 17 , 18 , 19 , 21 , 22 , 23 , 24 , 25 | ET10: Trade/migrate from another game | EU10: Trade/migrate from another game | EX10: Evolve Charmander / Charmeleon | EY10: Evolve Charmander / Charmeleon | EZ10: Not available in this game | FA10: Location data not yet available | FB10: Location data not yet available | FE10: Location data not yet available
A11: 0006-01 | B11: 6 | C11: Mega Charizard X | D11: =Sprite_Data!F3 | E11: =Sprite_Data!G3 | F11: =image("https://www.serebii.net/pokedex-bw/type/"&lower(H11)&".gif") | G11: =image("https://www.serebii.net/pokedex-bw/type/"&lower(I11)&".gif") | H11: Fire | I11: Dragon | J11: Flame Pokémon | K11: 1.7 m (5′07″) | L11: 110.5 kg (243.6 lbs) | M11: Tough Claws | P11: 3 Sp. Atk | Q11: 45 (5.9% with PokéBall, full HP) | R11: 50 (normal) | S11: 285 | T11: Medium Slow | U11: Dragon | V11: Monster | W11: 87.5% male, 12.5% female | X11: 20 (4,884–5,140 steps) | Y11: 78 | Z11: 130 | AA11: 111 | AB11: 130 | AC11: 85 | AD11: 100 | AE11: =sum(Y11:AD11) -> 634 | AF11: Charizardite X | AG11: 0006 | AH11: 0006 | AI11: 0006 | AJ11: 0231 | AK11: 0231 | AL11: 0231 | AP11: 0006 | AQ11: 0006 | AU11: 0236 | AV11: 0236 | BA11: 0085 | BB11: 0085 | BI11: 0006 | BJ11: 0006 | BK11: 0380 | BL11: 0380 | BV11: 0153
A12: 0006-02 | B12: 6 | C12: Mega Charizard Y | D12: =Sprite_Data!F4 | E12: =Sprite_Data!G4 | F12: =image("https://www.serebii.net/pokedex-bw/type/"&lower(H12)&".gif") | G12: =image("https://www.serebii.net/pokedex-bw/type/"&lower(I12)&".gif") | H12: Fire | I12: Flying | J12: Flame Pokémon | K12: 1.7 m (5′07″) | L12: 100.5 kg (221.6 lbs) | M12: Drought | P12: 3 Sp. Atk | Q12: 45 (5.9% with PokéBall, full HP) | R12: 50 (normal) | S12: 285 | T12: Medium Slow | U12: Dragon | V12: Monster | W12: 87.5% male, 12.5% female | X12: 20 (4,884–5,140 steps) | Y12: 78 | Z12: 104 | AA12: 78 | AB12: 159 | AC12: 115 | AD12: 100 | AE12: =sum(Y12:AD12) -> 634 | AF12: Charizardite Y | AG12: 0006 | AH12: 0006 | AI12: 0006 | AJ12: 0231 | AK12: 0231 | AL12: 0231 | AP12: 0006 | AQ12: 0006 | AU12: 0236 | AV12: 0236 | BA12: 0085 | BB12: 0085 | BI12: 0006 | BJ12: 0006 | BK12: 0380 | BL12: 0380 | BV12: 0153
A13: 0006-03 | B13: 6 | C13: Charizard Gigantamax | D13: =Sprite_Data!J3 | E13: =Sprite_Data!K3 | F13: =image("https://www.serebii.net/pokedex-bw/type/"&lower(H13)&".gif") | G13: =image("https://www.serebii.net/pokedex-bw/type/"&lower(I13)&".gif") | H13: Fire | I13: Flying | J13: Flame Pokémon | M13: Blaze | O13: Solar Power | AE13: =sum(Y13:AD13) -> 0 | AF13: Dynamax Band
A14: 0007-00 | B14: 7 | C14: Squirtle | D14: =image("https://img.pokemondb.net/sprites/home/normal/"& lower(C14) &".png") | E14: =image("https://img.pokemondb.net/sprites/home/shiny/"& lower(C14) &".png") | F14: =image("https://www.serebii.net/pokedex-bw/type/"&lower(H14)&".gif") | G14: =image("https://www.serebii.net/pokedex-bw/type/"&lower(I14)&".gif") | H14: Water | J14: Tiny Turtle Pokémon | K14: 0.5 m (1′08″) | L14: 9.0 kg (19.8 lbs) | M14: Torrent | O14: Rain Dish | P14: 1 Defense | Q14: 45 (5.9% with PokéBall, full HP) | R14: 50 (normal) | S14: 63 | T14: Medium Slow | U14: Monster | V14: Water 1 | W14: 87.5% male, 12.5% female | X14: 20 (4,884–5,140 steps) | Y14: 44 | Z14: 48 | AA14: 65 | AB14: 50 | AC14: 64 | AD14: 43 | AE14: =sum(Y14:AD14) -> 314 | AF14: Squirtle → Wartortle (Level 16) → Blastoise (Level 36) | AG14: 0007 | AH14: 0007 | AI14: 0007 | AJ14: 0232 | AK14: 0232 | AL14: 0232 | AP14: 0007 | AQ14: 0007 | AU14: 0237 | AV14: 0237 | BA14: 0086 | BB14: 0086 | BI14: 0007 | BJ14: 0007 | BM14: 0071 | BU14: 0170 | BV14: 0154 | BW14: After birth, its back swells and hardens into a shell. Powerfully sprays foam from its mouth. | BX14: After birth, its back swells and hardens into a shell. Powerfully sprays foam from its mouth. | BY14: Shoots water at prey while in the water. Withdraws into its shell when in danger. | BZ14: The shell is soft when it is born. It soon becomes so resilient, prodding fingers will bounce off it. | CA14: The shell, which hardens soon after it is born, is resilient. If you poke it, it will bounce back out. | CB14: When it feels threatened, it draws its legs inside its shell and sprays water from its mouth. | CC14: SQUIRTLE’s shell is not merely used for protection. The shell’s rounded shape and the grooves on its surface help minimize resistance in water, enabling this POKéMON to swim at high speeds. | CD14: SQUIRTLE’s shell is not merely used for protection. The shell’s rounded shape and the grooves on its surface help minimize resistance in water, enabling this POKéMON to swim at high speeds. | CE14: Its shell is not just for protection. Its rounded shape and the grooves on its surface minimize resistance in water, enabling SQUIRTLE to swim at high speeds. | CF14: When it retracts its long neck into its shell, it squirts out water with vigorous force. | CG14: After birth, its back swells and hardens into a shell. It powerfully sprays foam from its mouth. | CH14: It shelters itself in its shell, then strikes back with spouts of water at every opportunity. | CI14: It shelters itself in its shell, then strikes back with spouts of water at every opportunity. | CJ14: It shelters itself in its shell, then strikes back with spouts of water at every opportunity. | CK14: The shell is soft when it is born. It soon becomes so resilient, prodding fingers will bounce off it. | CL14: The shell, which hardens soon after it is born, is resilient. If you poke it, it will bounce back out. | CM14: It shelters itself in its shell, then strikes back with spouts of water at every opportunity. | CN14: It shelters itself in its shell, then strikes back with spouts of water at every opportunity. | CO14: It shelters itself in its shell then strikes back with spouts of water at every opportunity. | CP14: It shelters itself in its shell then strikes back with spouts of water at every opportunity. | CQ14: It shelters itself in its shell, then strikes back with spouts of water at every opportunity. | CR14: Shoots water at prey while in the water. Withdraws into its shell when in danger. | CS14: Squirtle’s shell is not merely used for protection. The shell’s rounded shape and the grooves on its surface help minimize resistance in water, enabling this Pokémon to swim at high speeds. | CT14: Squirtle’s shell is not merely used for protection. The shell’s rounded shape and the grooves on its surface help minimize resistance in water, enabling this Pokémon to swim at high speeds. | CY14: Shoots water at prey while in the water. Withdraws into its shell when in danger. | CZ14: Shoots water at prey while in the water. Withdraws into its shell when in danger. | DA14: When it retracts its long neck into its shell, it squirts out water with vigorous force. | DB14: When it feels threatened, it draws its limbs inside its shell and sprays water from its mouth. | DE14: It hides in its shell to protect itself, then strikes back with spouts of water at every opportunity. | DF14: It hides in its shell to protect itself, then strikes back with spouts of water at every opportunity. | DP14: Pallet Town | DQ14: Pallet Town | DR14: Vermilion City | DS14: Trade/migrate from another game | DT14: Trade/migrate from another game | DU14: Trade/migrate from another game | DV14: Trade/migrate from another game | DW14: Trade/migrate from another game | DX14: Trade/migrate from another game | DY14: Pallet Town | DZ14: Pallet Town | EA14: Trade/migrate from another game | EB14: Trade/migrate from another game | EC14: Trade/migrate from another game | ED14: Pallet Town | EE14: Pallet Town | EF14: Trade/migrate from another game | EG14: Trade/migrate from another game | EH14: Trade/migrate from another game | EI14: Trade/migrate from another game | EJ14: Lumiose City | EK14: Lumiose City | EL14: Trade/migrate from another game | EM14: Trade/migrate from another game | EN14: Trade/migrate from another game | EO14: Trade/migrate from another game | EP14: Seaward Cave | EQ14: Seaward Cave | ER14: Route 24 , 25 , Seafoam Islands , Vermilion City | ES14: Route 24 , 25 , Seafoam Islands , Vermilion City | ET14: Trade/migrate from another game | EU14: Trade/migrate from another game | EX14: Fountainspring Cave , Riverbank Cave , Still-Water Cavern | EY14: Fountainspring Cave , Riverbank Cave , Still-Water Cavern | EZ14: Not available in this game | FA14: Location data not yet available | FB14: Location data not yet available | FE14: Location data not yet available
A15: 0008-00 | B15: 8 | C15: Wartortle | D15: =image("https://img.pokemondb.net/sprites/home/normal/"& lower(C15) &".png") | E15: =image("https://img.pokemondb.net/sprites/home/shiny/"& lower(C15) &".png") | F15: =image("https://www.serebii.net/pokedex-bw/type/"&lower(H15)&".gif") | G15: =image("https://www.serebii.net/pokedex-bw/type/"&lower(I15)&".gif") | H15: Water | J15: Turtle Pokémon | K15: 1.0 m (3′03″) | L15: 22.5 kg (49.6 lbs) | M15: Torrent | O15: Rain Dish | P15: 1 Defense, 1 Sp. Def | Q15: 45 (5.9% with PokéBall, full HP) | R15: 50 (normal) | S15: 142 | T15: Medium Slow | U15: Monster | V15: Water 1 | W15: 87.5% male, 12.5% female | X15: 20 (4,884–5,140 steps) | Y15: 59 | Z15: 63 | AA15: 80 | AB15: 65 | AC15: 80 | AD15: 58 | AE15: =sum(Y15:AD15) -> 405 | AF15: Squirtle → Wartortle (Level 16) → Blastoise (Level 36) | AG15: 0008 | AH15: 0008 | AI15: 0008 | AJ15: 0233 | AK15: 0233 | AL15: 0233 | AP15: 0008 | AQ15: 0008 | AU15: 0238 | AV15: 0238 | BA15: 0087 | BB15: 0087 | BI15: 0008 | BJ15: 0008 | BM15: 0072 | BU15: 0171 | BV15: 0155 | BW15: Often hides in water to stalk unwary prey. For swimming fast, it moves its ears to maintain balance. | BX15: Often hides in water to stalk unwary prey. For swimming fast, it moves its ears to maintain balance. | BY15: When tapped, this POKéMON will pull in its head, but its tail will still stick out a little bit. | BZ15: It is recognized as a symbol of longevity. If its shell has algae on it, that WARTORTLE is very old. | CA15: It cleverly controls its furry ears and tail to maintain its balance while swimming. | CB15: Its long, furry tail is a symbol of longevity, making it quite popular among older people. | CC15: Its tail is large and covered with a rich, thick fur. The tail becomes increasingly deeper in color as WARTORTLE ages. The scratches on its shell are evidence of this POKéMON’s toughness as a battler. | CD15: Its tail is large and covered with a rich, thick fur. The tail becomes increasingly deeper in color as WARTORTLE ages. The scratches on its shell are evidence of this POKéMON’s toughness as a battler. | CE15: Its large tail is covered with rich, thick fur that deepens in color with age. The scratches on its shell are evidence of this POKéMON’s toughness in battle. | CF15: This POKéMON is very popular as a pet. Its fur-covered tail is a symbol of its longevity. | CG15: It often hides in water to stalk unwary prey. For fast swimming, it moves its ears to maintain balance. | CH15: It is said to live 10,000 years. Its furry tail is popular as a symbol of longevity. | CI15: It is said to live 10,000 years. Its furry tail is popular as a symbol of longevity. | CJ15: It is said to live 10,000 years. Its furry tail is popular as a symbol of longevity. | CK15: It is a well-established symbol of longevity. If its shell has algae on it, that WARTORTLE is very old. | CL15: It cleverly controls its furry ears and tail to maintain its balance while swimming. | CM15: It is said to live 10,000 years. Its furry tail is popular as a symbol of longevity. | CN15: It is said to live 10,000 years. Its furry tail is popular as a symbol of longevity. | CO15: It is said to live 10,000 years. Its furry tail is popular as a symbol of longevity. | CP15: It is said to live 10,000 years. Its furry tail is popular as a symbol of longevity. | CQ15: When tapped, this Pokémon will pull in its head, but its tail will still stick out a little bit. | CR15: It is said to live 10,000 years. Its furry tail is popular as a symbol of longevity. | CS15: Its tail is large and covered with a rich, thick fur. The tail becomes increasingly deeper in color as Wartortle ages. The scratches on its shell are evidence of this Pokémon’s toughness as a battler. | CT15: Its tail is large and covered with a rich, thick fur. The tail becomes increasingly deeper in color as Wartortle ages. The scratches on its shell are evidence of this Pokémon’s toughness as a battler. | CY15: When tapped on its head, this Pokémon will pull it in, but its tail will stick out a little bit. | CZ15: When tapped on its head, this Pokémon will pull it in, but its tail will stick out a little bit. | DA15: It is recognized as a symbol of longevity. If its shell has algae on it, that Wartortle is very old. | DB15: It cleverly controls its furry ears and tail to maintain its balance while swimming. | DE15: It is said to live 10,000 years. Its furry tail is popular as a symbol of longevity. | DF15: It is said to live 10,000 years. Its furry tail is popular as a symbol of longevity. | DP15: Evolve Squirtle | DQ15: Evolve Squirtle | DR15: Evolve Squirtle | DS15: Trade/migrate from another game | DT15: Trade/migrate from another game | DU15: Trade/migrate from another game | DV15: Trade/migrate from another game | DW15: Trade/migrate from another game | DX15: Trade/migrate from another game | DY15: Evolve Squirtle | DZ15: Evolve Squirtle | EA15: Trade/migrate from another game | EB15: Trade/migrate from another game | EC15: Trade/migrate from another game | ED15: Evolve Squirtle | EE15: Evolve Squirtle | EF15: Trade/migrate from another game | EG15: Trade/migrate from another game | EH15: Trade/migrate from another game | EI15: Trade/migrate from another game | EJ15: Evolve Squirtle | EK15: Evolve Squirtle | EL15: Trade/migrate from another game | EM15: Trade/migrate from another game | EN15: Trade/migrate from another game | EO15: Trade/migrate from another game | EP15: Evolve Squirtle | EQ15: Evolve Squirtle | ER15: Evolve Squirtle | ES15: Evolve Squirtle | ET15: Trade/migrate from another game | EU15: Trade/migrate from another game | EX15: Evolve Squirtle | EY15: Evolve Squirtle | EZ15: Not available in this game | FA15: Location data not yet available | FB15: Location data not yet available | FE15: Location data not yet available
